#VRML_SIM R2025a utf8

EXTERNPROTO "https://raw.githubusercontent.com/cyberbotics/webots/R2025a/projects/objects/floors/protos/RectangleArena.proto"
EXTERNPROTO "https://raw.githubusercontent.com/cyberbotics/webots/R2025a/projects/objects/apartment_structure/protos/Wall.proto"
EXTERNPROTO "https://raw.githubusercontent.com/cyberbotics/webots/R2025a/projects/appearances/protos/BrushedAluminium.proto"
EXTERNPROTO "https://raw.githubusercontent.com/cyberbotics/webots/R2025a/projects/objects/backgrounds/protos/TexturedBackground.proto"
EXTERNPROTO "https://raw.githubusercontent.com/cyberbotics/webots/R2025a/projects/objects/backgrounds/protos/TexturedBackgroundLight.proto"
EXTERNPROTO "https://raw.githubusercontent.com/cyberbotics/webots/R2025a/projects/appearances/protos/Roughcast.proto"
EXTERNPROTO "https://raw.githubusercontent.com/cyberbotics/webots/R2025a/projects/objects/solids/protos/SolidBox.proto"

WorldInfo {
}
Viewpoint {
  orientation -0.11044960368557284 0.9628940313747806 0.24624371949051424 0.8718931420544974
  position -4.661246004599556 0.5048328772079649 4.386724980650456
}
TexturedBackground {
}
TexturedBackgroundLight {
}
DirectionalLight {
  direction 0.3 -0.5 -0.7
  intensity 1.5
}
RectangleArena {
  floorSize 3.048 3.048
  floorAppearance PBRAppearance {
    baseColor 0 0 0
    roughness 1
    metalness 0
  }
  wallHeight 0.6096
  wallAppearance BrushedAluminium {
    IBLStrength 0
  }
}
Wall {
  translation 1.52 -0.38 0
  name "wall(2)"
  size 0.01 0.3048 0.3048
  appearance Roughcast {
    colorOverride 1 1 0
    textureTransform TextureTransform {
      scale 2.4 1
    }
  }
}
Wall {
  translation 0.29 -0.46 0
  name "wall(8)"
  size 0.01 1 0.3048
}
Wall {
  translation 0.29 1.01 0
  rotation 0 0 1 1.5708
  name "wall(11)"
  size 0.01 1 0.3048
}
Wall {
  translation -0.87 0.19 0
  name "wall(9)"
  size 0.01 1 0.3048
}
Wall {
  translation 0.98 0.49 0
  rotation 0 0 1 -1.5707953071795862
  name "wall(10)"
  size 0.01 1 0.3048
}
Wall {
  translation 1.52 -0.38 0
  rotation 0 1 0 -1.5707953071795862
  name "wall(7)"
  size 0.01 0.3048 0.3048
  appearance Roughcast {
    colorOverride 1 1 0
    textureTransform TextureTransform {
      scale 2.4 1
    }
  }
}
Wall {
  translation 1.52 0.71 0
  name "wall(3)"
  size 0.01 0.3048 0.3048
  appearance Roughcast {
    colorOverride 1 0 0
    textureTransform TextureTransform {
      scale 2.4 1
    }
  }
}
Wall {
  translation 1.52 0.71 0
  rotation 0 1 0 -1.5707953071795862
  name "wall(6)"
  size 0.01 0.3048 0.3048
  appearance Roughcast {
    colorOverride 1 0 0
    textureTransform TextureTransform {
      scale 2.4 1
    }
  }
}
Wall {
  translation -1.52 -0.38 0
  size 0.01 0.3048 0.3048
  appearance Roughcast {
    colorOverride 0 1 0
    textureTransform TextureTransform {
      scale 2.4 1
    }
  }
}
Wall {
  translation -1.52 -0.38 0
  rotation 0 1 0 1.5708
  name "wall(5)"
  size 0.01 0.3048 0.3048
  appearance Roughcast {
    colorOverride 0 1 0
    textureTransform TextureTransform {
      scale 2.4 1
    }
  }
}
Wall {
  translation -1.52 0.77 0
  name "wall(1)"
  size 0.01 0.3048 0.3048
  appearance Roughcast {
    colorOverride 0 0 1
    textureTransform TextureTransform {
      scale 2.4 1
    }
  }
}
Wall {
  translation -1.52 0.77 0
  rotation 0 1 0 1.5708
  name "wall(4)"
  size 0.01 0.3048 0.3048
  appearance Roughcast {
    colorOverride 0 0 1
    textureTransform TextureTransform {
      scale 2.4 1
    }
  }
}
SolidBox {
  translation -0.441667 -0.255 0.1
  rotation 0 0 1 0.523599
  name "red_box"
  size 0.15 0.15 0.15
  appearance PBRAppearance {
    baseColor 1 0 0
    roughness 0.5
    metalness 0
  }
}
SolidBox {
  translation 0.733344 0.733346 0.1
  rotation 0 0 1 -0.785395307179586
  name "green_box"
  size 0.15 0.15 0.15
  appearance PBRAppearance {
    baseColor 0 1 0
    roughness 0.5
    metalness 0
  }
}
SolidBox {
  translation -0.5 0.5 0.1
  rotation 0 0 1 -0.523595307179586
  name "blue_box"
  size 0.15 0.15 0.15
  appearance PBRAppearance {
    baseColor 0 0 1
    roughness 0.5
    metalness 0
  }
}
SolidBox {
  translation 0.62 -0.292156 0.1
  rotation 0 0 1 1.0472
  name "yellow_box"
  size 0.15 0.15 0.15
  appearance PBRAppearance {
    baseColor 1 1 0
    roughness 0.5
    metalness 0
  }
}
SolidBox {
  translation -0.5 -1.01 0.1
  name "cyan_box"
  size 0.15 0.15 0.15
  appearance PBRAppearance {
    baseColor 0 1 1
    roughness 0.5
    metalness 0
  }
}
SolidBox {
  translation 0.753426 -1.00187 0.1
  rotation 0 0 -1 0.261797
  name "purple_box"
  size 0.15 0.15 0.15
  appearance PBRAppearance {
    baseColor 0.5 0 0.5
    roughness 0.5
    metalness 0
  }
}
DEF BBAlr8 Robot {
  translation 0.000133008 0.224076 0.525128
  rotation -0.9999753675941232 0.00011925811870603285 -0.00701783317691477 0.04467094081207809
  children [
    DEF frontCam Camera {
      translation 2.1522e-07 -0.181 0.06
      rotation -4.2638199999214016e-06 -4.322939999920311e-06 -0.9999999999815661 -1.5707953071795862
      children [
        DEF fcam Shape {
          appearance PBRAppearance {
            baseColor 1 0 0
          }
          geometry Capsule {
            height 0.002
            radius 0.004
          }
          castShadows FALSE
        }
      ]
      name "fcam"
      boundingObject USE fcam
      physics Physics {
      }
      fieldOfView 2.7854
      width 256
      height 256
    }
    DEF castorFront Solid {
      translation 0 0.025 -0.015
      children [
        DEF castor Shape {
          appearance PBRAppearance {
          }
          geometry Sphere {
            radius 0.005
          }
          castShadows FALSE
        }
      ]
      boundingObject USE castor
      physics Physics {
      }
    }
    DEF castorBack Solid {
      translation 0 -0.025 -0.0141
      children [
        DEF castor Shape {
          appearance PBRAppearance {
          }
          geometry Sphere {
            radius 0.005
          }
          castShadows FALSE
        }
      ]
      name "solid(1)"
      boundingObject USE castor
      physics Physics {
      }
    }
    HingeJoint {
      jointParameters HingeJointParameters {
        anchor 0.181 0 -0.03
      }
      device [
        PositionSensor {
          name "leftEncoder"
        }
        RotationalMotor {
          name "leftMotor"
          maxVelocity 100
          maxTorque 100
        }
      ]
      endPoint Solid {
        translation 0.181 0 -0.03
        rotation -0.128900729092946 -0.9916575023864374 -3.1496344614446366e-09 4.677688464779303
        children [
          DEF leftWheel Shape {
            appearance PBRAppearance {
              baseColorMap ImageTexture {
                url [
                  "../assets/wheel.jpg"
                ]
              }
            }
            geometry Cylinder {
              height 0.01
              radius 0.03
            }
            castShadows FALSE
          }
        ]
        name "leftWheel"
        boundingObject USE leftWheel
        physics Physics {
        }
      }
    }
    HingeJoint {
      jointParameters HingeJointParameters {
        anchor -0.181 0 -0.03
      }
      device [
        DEF rightEncoder PositionSensor {
          name "rightEncoder"
        }
        DEF rightMotor RotationalMotor {
          name "rightMotor"
          maxVelocity 100
          maxTorque 100
        }
      ]
      endPoint Solid {
        translation -0.181 0 -0.03
        rotation -6.280358323737861e-15 1 -3.1401791618689305e-16 1.5707999925117857
        children [
          DEF rightWheel Shape {
            appearance PBRAppearance {
              baseColorMap ImageTexture {
                url [
                  "../assets/wheel.jpg"
                ]
                filtering 5
              }
              textureTransform TextureTransform {
              }
            }
            geometry Cylinder {
              height 0.01
              radius 0.03
            }
            castShadows FALSE
          }
        ]
        name "rightWheel"
        boundingObject USE rightWheel
        physics Physics {
        }
      }
    }
    DEF body Shape {
      appearance PBRAppearance {
        metalness 0.5
      }
      geometry Cylinder {
        height 0.1
        radius 0.177
      }
      castShadows FALSE
    }
  ]
  boundingObject USE body
  physics Physics {
    centerOfMass [
      0 0 0
    ]
  }
  controller "bbAlr8"
}
