#VRML_SIM R2025a utf8

EXTERNPROTO "https://raw.githubusercontent.com/cyberbotics/webots/R2025a/projects/objects/floors/protos/RectangleArena.proto"
EXTERNPROTO "https://raw.githubusercontent.com/cyberbotics/webots/R2025a/projects/objects/apartment_structure/protos/Wall.proto"
EXTERNPROTO "https://raw.githubusercontent.com/cyberbotics/webots/R2025a/projects/appearances/protos/BrushedAluminium.proto"
EXTERNPROTO "https://raw.githubusercontent.com/cyberbotics/webots/R2025a/projects/objects/backgrounds/protos/TexturedBackground.proto"
EXTERNPROTO "https://raw.githubusercontent.com/cyberbotics/webots/R2025a/projects/objects/backgrounds/protos/TexturedBackgroundLight.proto"
EXTERNPROTO "https://raw.githubusercontent.com/cyberbotics/webots/R2025a/projects/appearances/protos/Roughcast.proto"

WorldInfo {
}
Viewpoint {
  orientation -0.36375496700451254 0.4800085795124893 0.798294486749062 1.5187817952129992
  position -2.5028297957576067 -5.327325193785998 6.571693281007842
}
TexturedBackground {
}
TexturedBackgroundLight {
}
DirectionalLight {
  direction 0.3 -0.5 -0.7
  intensity 1.5
}
RectangleArena {
  floorSize 3.048 3.048
  floorAppearance PBRAppearance {
    baseColor 0 0 0
    roughness 1
    metalness 0
  }
  wallHeight 0.6096
  wallAppearance BrushedAluminium {
    IBLStrength 0
  }
}
Wall {
  translation 1.52 -0.78 0
  name "wall(2)"
  size 0.01 0.4 0.4
  appearance Roughcast {
    colorOverride 1 0 0
    textureTransform TextureTransform {
      scale 2.4 1
    }
  }
}
Wall {
  translation -0.16 -1.28 0
  rotation 0 0 1 1.5708
  name "wall(8)"
  size 0.1 0.375 0.125
}
Wall {
  translation -0.87 0.19 0
  name "wall(9)"
  size 0.125 0.375 0.105
}
Wall {
  translation 0.97 -0.1 0
  name "wall(12)"
  size 0.125 0.375 0.105
}
Wall {
  translation 0.84 -1.18 0
  rotation 0 0 1 -1.5707953071795862
  name "wall(10)"
  size 0.1 0.375 0.125
}
Wall {
  translation 1.52 -0.78 0
  rotation 0 1 0 -1.5707953071795862
  name "wall(7)"
  size 0.001 0.4 0.4
  appearance Roughcast {
    colorOverride 1 0 0
    textureTransform TextureTransform {
      scale 2.4 1
    }
  }
}
Wall {
  translation 1.52 0.61 0
  name "wall(3)"
  size 0.01 0.4 0.4
  appearance Roughcast {
    colorOverride 0 1 1
    textureTransform TextureTransform {
      scale 2.4 1
    }
  }
}
Wall {
  translation 1.52 0.61 0
  rotation 0 1 0 -1.5707953071795862
  name "wall(6)"
  size 0.001 0.4 0.4
  appearance Roughcast {
    colorOverride 0 1 1
    textureTransform TextureTransform {
      scale 2.4 1
    }
  }
}
Wall {
  translation 0.26 1.31 1.28473e-06
  rotation 0 1 0 -1.5707953071795862
  name "wall(11)"
  size 0.001 0.4 0.4
}
Wall {
  translation -1.52 -0.78 0
  size 0.01 0.4 0.4
  appearance Roughcast {
    colorOverride 0 1 0
    textureTransform TextureTransform {
      scale 2.4 1
    }
  }
}
Wall {
  translation -1.52 -0.78 0
  rotation 0 1 0 1.5708
  name "wall(5)"
  size 0.001 0.4 0.4
  appearance Roughcast {
    colorOverride 0 1 0
    textureTransform TextureTransform {
      scale 2.4 1
    }
  }
}
Wall {
  translation -1.52 0.61 0
  name "wall(1)"
  size 0.01 0.4 0.4
  appearance Roughcast {
    colorOverride 1 1 0
    textureTransform TextureTransform {
      scale 2.4 1
    }
  }
}
Wall {
  translation -1.52 0.61 0
  rotation 0 1 0 1.5708
  name "wall(4)"
  size 0.001 0.4 0.4
  appearance Roughcast {
    colorOverride 1 1 0
    textureTransform TextureTransform {
      scale 2.4 1
    }
  }
}
Solid {
  translation 0.3160178830336076 -0.9560296309371286 0.03733448182751615
  rotation -7.297478033298092e-17 4.5420951764431735e-17 -1 1.4707225602854175
  children [
    DEF rbox Shape {
      appearance PBRAppearance {
        baseColor 1 0 0
        roughness 0.5
        metalness 0
      }
      geometry Box {
        size 0.075 0.075 0.075
      }
    }
  ]
  name "red_box"
  boundingObject USE rbox
  physics Physics {
  }
  linearVelocity 2.0115314007770248e-17 2.223364932625428e-17 -2.0003058266917235e-07
  angularVelocity 2.8070824128794155e-16 8.421247238638223e-16 -2.2310895514404623e-16
}
Solid {
  translation -0.6698755787164241 -0.23092883593636268 0.037334481827516135
  rotation -5.769750894899307e-17 -1.6840881800146509e-18 1 1.7779103020404803
  children [
    DEF gbox Shape {
      appearance PBRAppearance {
        baseColor 0 1 0
        roughness 0.5
        metalness 0
      }
      geometry Box {
        size 0.075 0.075 0.075
      }
    }
  ]
  name "green_box"
  boundingObject USE gbox
  physics Physics {
  }
  linearVelocity 3.208843680965585e-17 -2.876908961502413e-17 -2.0003058260180576e-07
  angularVelocity 4.2106236193190394e-16 -2.807082412879503e-16 2.571100084945398e-16
}
Solid {
  translation -0.20648274280939835 -1.192663027280757 0.03733445705033053
  rotation 0.707713457657504 -0.7064991580982513 0.0007755365383327378 3.1400550629552724
  children [
    DEF wbox Shape {
      appearance PBRAppearance {
        roughness 0.5
        metalness 0
      }
      geometry Box {
        size 0.075 0.075 0.075
      }
    }
  ]
  name "white_box"
  boundingObject USE wbox
  physics Physics {
  }
  linearVelocity 1.941745526108473e-06 9.638360024846146e-06 1.9608594612516475e-06
  angularVelocity 0.0001036195452903002 5.111289154445486e-05 -9.858346887870802e-05
}
Solid {
  translation -0.7276629379464747 0.7329555131833626 0.037334481827516135
  rotation -2.1535957785806073e-17 -1.983281035610617e-16 1 1.2921498387510835
  children [
    DEF ybox Shape {
      appearance PBRAppearance {
        baseColor 1 1 0
        roughness 0.5
        metalness 0
      }
      geometry Box {
        size 0.075 0.075 0.075
      }
    }
  ]
  name "yellow_box"
  boundingObject USE ybox
  physics Physics {
  }
  linearVelocity -3.3327153021326616e-17 1.3185186011372173e-17 -2.000305825343528e-07
  angularVelocity 1.4035412064397097e-16 -1.1228329651517638e-15 -3.4113433662501125e-17
}
Solid {
  translation 0.3538308794342245 0.3055841423136196 0.03733448182751614
  rotation 3.307125481806594e-16 -8.547458351537181e-17 -1 0.4663911557286901
  children [
    DEF bbox Shape {
      appearance PBRAppearance {
        baseColor 0 1 1
        roughness 0.5
        metalness 0
      }
      geometry Box {
        size 0.075 0.075 0.075
      }
    }
  ]
  name "cyan_box"
  boundingObject USE bbox
  physics Physics {
  }
  linearVelocity 3.358966629958133e-17 -3.517386353257167e-17 -2.0003058266916187e-07
  angularVelocity 7.01770603219852e-16 -1.122832965151763e-15 4.176034588663898e-17
}
DEF BBAlr8 Robot {
  translation -0.1060511274280818 0.42176589017547056 0.05596361360461105
  rotation 0.005038030645085076 0.004271292884516243 0.9999781869142516 1.499224934952516
  children [
    Display {
      children [
        DEF disp Shape {
          geometry Box {
            size 0.01 0.01 0.01
          }
        }
      ]
      boundingObject USE disp
      physics Physics {
      }
      width 640
      height 480
    }
    DEF gyro Gyro {
      children [
        DEF gyroS Shape {
          geometry Sphere {
            radius 0.01
          }
        }
      ]
      boundingObject USE gyroS
      physics Physics {
      }
    }
    Solid {
      translation 0.11 -0.2 0
      children [
        DEF leftArm Shape {
          appearance PBRAppearance {
            baseColor 0 0 0
          }
          geometry Box {
            size 0.02 0.15 0.09
          }
        }
      ]
      name "solid(2)"
      boundingObject USE leftArm
      physics Physics {
      }
    }
    Solid {
      translation -0.11 -0.2 0
      children [
        DEF rightArm Shape {
          appearance PBRAppearance {
            baseColor 0 0 0
          }
          geometry Box {
            size 0.02 0.15 0.09
          }
        }
      ]
      name "solid(3)"
      boundingObject USE rightArm
      physics Physics {
      }
    }
    DEF frontCam Camera {
      translation -0.00497507 -0.0650495 0.090495
      rotation 0 0 -1 1.5708
      children [
        DEF fcam Shape {
          appearance PBRAppearance {
            baseColor 1 0 0
          }
          geometry Capsule {
            height 0.012
            radius 0.04
          }
          castShadows FALSE
        }
      ]
      name "fcam"
      boundingObject USE fcam
      physics Physics {
      }
      fieldOfView 1
      width 640
      height 480
    }
    DEF castorFront Solid {
      translation 0 -0.15 -0.051
      children [
        DEF castor Shape {
          appearance PBRAppearance {
          }
          geometry Sphere {
            radius 0.005
          }
          castShadows FALSE
        }
      ]
      boundingObject USE castor
      physics Physics {
      }
    }
    DEF castorBack Solid {
      translation 0 0.149 -0.051
      children [
        DEF castor Shape {
          appearance PBRAppearance {
          }
          geometry Sphere {
            radius 0.005
          }
          castShadows FALSE
        }
      ]
      name "solid(1)"
      boundingObject USE castor
      physics Physics {
      }
    }
    HingeJoint {
      jointParameters HingeJointParameters {
        position 2738.3687209541
        anchor 0.181 0 -0.03
      }
      device [
        PositionSensor {
          name "leftEncoder"
        }
        RotationalMotor {
          name "leftMotor"
          maxVelocity 100
          maxTorque 100
        }
      ]
      endPoint Solid {
        translation 0.18160993891107124 -5.942768903454198e-06 -0.029997762383409222
        rotation 0.7029172249755051 -0.11871949922095945 0.7012938437897908 3.3943504034014413
        children [
          DEF leftWheel Shape {
            appearance PBRAppearance {
              baseColorMap ImageTexture {
                url [
                  "../assets/wheel.jpg"
                ]
              }
            }
            geometry Cylinder {
              height 0.01
              radius 0.03
            }
            castShadows FALSE
          }
        ]
        name "leftWheel"
        boundingObject USE leftWheel
        physics Physics {
        }
        linearVelocity -6.697776246320033e-12 9.925408438373257e-11 1.2565269820367107e-14
        angularVelocity -1.9032623870865495e-10 -2.8379982942242744e-09 -3.299829036047497e-09
      }
    }
    HingeJoint {
      jointParameters HingeJointParameters {
        position 2748.6810410889007
        anchor -0.181 0 -0.03
      }
      device [
        DEF rightEncoder PositionSensor {
          name "rightEncoder"
        }
        DEF rightMotor RotationalMotor {
          name "rightMotor"
          maxVelocity 100
          maxTorque 100
        }
      ]
      endPoint Solid {
        translation -0.1815837872808982 -9.778887432040546e-05 -0.029850360201369663
        rotation -0.7083801388438123 -0.07766819665956161 -0.7015448881712936 3.2867599809070382
        children [
          DEF rightWheel Shape {
            appearance PBRAppearance {
              baseColorMap ImageTexture {
                url [
                  "../assets/wheel.jpg"
                ]
                filtering 5
              }
              textureTransform TextureTransform {
              }
            }
            geometry Cylinder {
              height 0.01
              radius 0.03
            }
            castShadows FALSE
          }
        ]
        name "rightWheel"
        boundingObject USE rightWheel
        physics Physics {
        }
        linearVelocity -1.2088940514822506e-09 1.851625008566835e-10 6.081531010337888e-14
        angularVelocity -3.4578279986177783e-09 -4.840203003230529e-08 -3.318889456017694e-09
      }
    }
    DEF body Shape {
      appearance PBRAppearance {
        metalness 0.5
      }
      geometry Cylinder {
        height 0.1
        radius 0.177
      }
      castShadows FALSE
    }
  ]
  boundingObject USE body
  physics Physics {
    centerOfMass [
      0 0 0
    ]
  }
  controller "bbAlr8"
  cpuConsumption 20
  linearVelocity -6.081654862235623e-10 1.010917433488328e-10 -2.216764033854552e-12
  angularVelocity 1.2081143661653176e-11 -1.4645713447937795e-11 -3.2986467862365585e-09
}
