#VRML_SIM R2025a utf8

EXTERNPROTO "https://raw.githubusercontent.com/cyberbotics/webots/R2025a/projects/objects/floors/protos/RectangleArena.proto"
EXTERNPROTO "https://raw.githubusercontent.com/cyberbotics/webots/R2025a/projects/objects/apartment_structure/protos/Wall.proto"
EXTERNPROTO "https://raw.githubusercontent.com/cyberbotics/webots/R2025a/projects/appearances/protos/BrushedAluminium.proto"
EXTERNPROTO "https://raw.githubusercontent.com/cyberbotics/webots/R2025a/projects/objects/backgrounds/protos/TexturedBackground.proto"
EXTERNPROTO "https://raw.githubusercontent.com/cyberbotics/webots/R2025a/projects/objects/backgrounds/protos/TexturedBackgroundLight.proto"
EXTERNPROTO "https://raw.githubusercontent.com/cyberbotics/webots/R2025a/projects/appearances/protos/Roughcast.proto"

WorldInfo {
}
Viewpoint {
  orientation 0.5074044470608817 0.629581372851272 -0.5883604524962128 1.880391620839714
  position 0.319543398053739 1.3364928487525867 4.424004833759616
}
TexturedBackground {
}
TexturedBackgroundLight {
}
DirectionalLight {
  direction 0.3 -0.5 -0.7
  intensity 1.5
}
RectangleArena {
  floorSize 3.048 3.048
  floorAppearance PBRAppearance {
    baseColor 0 0 0
    roughness 1
    metalness 0
  }
  wallHeight 0.6096
  wallAppearance BrushedAluminium {
    IBLStrength 0
  }
}
Wall {
  translation 1.52 -0.78 0
  name "wall(2)"
  size 0.01 0.4 0.4
  appearance Roughcast {
    colorOverride 1 0 0
    textureTransform TextureTransform {
      scale 2.4 1
    }
  }
}
Wall {
  translation -0.16 -0.74 0
  rotation 0 0 1 1.5708
  name "wall(8)"
  size 0.01 0.3 0.3048
}
Wall {
  translation -0.87 0.19 0
  name "wall(9)"
  size 0.01 0.3 0.3048
}
Wall {
  translation 0.84 -1.18 0
  rotation 0 0 1 -1.5707953071795862
  name "wall(10)"
  size 0.01 0.3 0.3048
}
Wall {
  translation 1.52 -0.78 0
  rotation 0 1 0 -1.5707953071795862
  name "wall(7)"
  size 0.001 0.4 0.4
  appearance Roughcast {
    colorOverride 1 0 0
    textureTransform TextureTransform {
      scale 2.4 1
    }
  }
}
Wall {
  translation 1.52 0.61 0
  name "wall(3)"
  size 0.01 0.4 0.4
  appearance Roughcast {
    colorOverride 0 1 1
    textureTransform TextureTransform {
      scale 2.4 1
    }
  }
}
Wall {
  translation 1.52 0.61 0
  rotation 0 1 0 -1.5707953071795862
  name "wall(6)"
  size 0.001 0.4 0.4
  appearance Roughcast {
    colorOverride 0 1 1
    textureTransform TextureTransform {
      scale 2.4 1
    }
  }
}
Wall {
  translation 0.26 1.31 1.28473e-06
  rotation 0 1 0 -1.5707953071795862
  name "wall(11)"
  size 0.001 0.4 0.4
}
Wall {
  translation -1.52 -0.78 0
  size 0.01 0.4 0.4
  appearance Roughcast {
    colorOverride 0 1 0
    textureTransform TextureTransform {
      scale 2.4 1
    }
  }
}
Wall {
  translation -1.52 -0.78 0
  rotation 0 1 0 1.5708
  name "wall(5)"
  size 0.001 0.4 0.4
  appearance Roughcast {
    colorOverride 0 1 0
    textureTransform TextureTransform {
      scale 2.4 1
    }
  }
}
Wall {
  translation -1.52 0.61 0
  name "wall(1)"
  size 0.01 0.4 0.4
  appearance Roughcast {
    colorOverride 1 1 0
    textureTransform TextureTransform {
      scale 2.4 1
    }
  }
}
Wall {
  translation -1.52 0.61 0
  rotation 0 1 0 1.5708
  name "wall(4)"
  size 0.001 0.4 0.4
  appearance Roughcast {
    colorOverride 1 1 0
    textureTransform TextureTransform {
      scale 2.4 1
    }
  }
}
Solid {
  translation 0.477324 -0.786743 0.07367565000000004
  rotation -1.1576978372877079e-16 -6.329749843359701e-17 1 0.523599
  children [
    Shape {
      appearance PBRAppearance {
        baseColor 1 0 0
        roughness 0.5
        metalness 0
      }
      geometry Box {
        size 0.15 0.15 0.15
      }
    }
  ]
  name "red_box"
  boundingObject Box {
    size 0.15 0.15 0.15
  }
  physics Physics {
  }
  linearVelocity 7.007636494296571e-17 1.6337589823783462e-17 -6.737788848194081e-17
  angularVelocity -3.5088530160992373e-16 1.1228329651517617e-15 1.0671554233262018e-16
}
Solid {
  translation -0.8892320582121507 -1.18984591775451 0.07367565000000001
  rotation 0.9369194995219867 -0.24716578587606952 -0.24716578587606958 1.6359081838648981
  children [
    Shape {
      appearance PBRAppearance {
        baseColor 0 1 0
        roughness 0.5
        metalness 0
      }
      geometry Box {
        size 0.15 0.15 0.15
      }
    }
  ]
  name "green_box"
  boundingObject Box {
    size 0.15 0.15 0.15
  }
  physics Physics {
  }
  linearVelocity -9.041744547511506e-17 -1.6253850122576035e-16 -1.345393080370381e-16
  angularVelocity 2.2807544599142522e-15 -1.263187085689367e-15 -1.2315567398218743e-18
}
Solid {
  translation -0.006073784898118671 0.11714769126389503 0.07367564999999987
  rotation 1.5827397500837226e-14 2.5400084295063234e-14 -1 1.0806630833727853
  children [
    Shape {
      appearance PBRAppearance {
        roughness 0.5
        metalness 0
      }
      geometry Box {
        size 0.15 0.15 0.15
      }
    }
  ]
  name "white_box"
  boundingObject Box {
    size 0.15 0.15 0.15
  }
  physics Physics {
  }
  linearVelocity -8.159144476847252e-15 1.5859954286288073e-14 1.0037692460052647e-15
  angularVelocity -2.1148999171260777e-13 -1.0848274208467252e-13 1.2536785554277796e-16
}
Solid {
  translation -0.5976480652747647 0.5781719229683006 0.07367565000000002
  rotation 4.566333773677403e-18 6.047685708719795e-17 1 0.8747069927423239
  children [
    Shape {
      appearance PBRAppearance {
        baseColor 1 1 0
        roughness 0.5
        metalness 0
      }
      geometry Box {
        size 0.15 0.15 0.15
      }
    }
  ]
  name "yellow_box"
  boundingObject Box {
    size 0.15 0.15 0.15
  }
  physics Physics {
  }
  linearVelocity -2.2833640642897707e-17 4.7552146314226293e-17 -1.3473984680213728e-16
  angularVelocity -7.368619857465489e-16 -6.666827669963234e-16 1.8213828292228915e-16
}
Solid {
  translation 0.53 0.38 0.07367565000000002
  rotation -0.3888124482391914 0.5832186723585278 0.7132186623375766 2.3102819269025365e-17
  children [
    Shape {
      appearance PBRAppearance {
        baseColor 0 1 1
        roughness 0.5
        metalness 0
      }
      geometry Box {
        size 0.15 0.15 0.15
      }
    }
  ]
  name "cyan_box"
  boundingObject Box {
    size 0.15 0.15 0.15
  }
  physics Physics {
  }
  linearVelocity -4.469578029847642e-17 -6.805577439173464e-18 -1.3503333143364262e-16
  angularVelocity 1.403541206439689e-16 -1.1228329651517634e-15 -5.242356723035854e-18
}
DEF BBAlr8 Robot {
  translation 0.0610292 1.33466 0.0624972
  rotation 1 0 0 0
  children [
    Solid {
      translation 0.11 -0.2 0
      children [
        DEF leftArm Shape {
          appearance PBRAppearance {
            baseColor 0 0 0
          }
          geometry Box {
            size 0.02 0.15 0.09
          }
        }
      ]
      name "solid(2)"
      boundingObject USE leftArm
      physics Physics {
      }
    }
    Solid {
      translation -0.11 -0.2 0
      children [
        DEF rightArm Shape {
          appearance PBRAppearance {
            baseColor 0 0 0
          }
          geometry Box {
            size 0.02 0.15 0.09
          }
        }
      ]
      name "solid(3)"
      boundingObject USE rightArm
      physics Physics {
      }
    }
    DEF frontCam Camera {
      translation -0.00497507 -0.0650495 0.090495
      rotation 0 0 -1 1.5708
      children [
        DEF fcam Shape {
          appearance PBRAppearance {
            baseColor 1 0 0
          }
          geometry Capsule {
            height 0.012
            radius 0.04
          }
          castShadows FALSE
        }
      ]
      name "fcam"
      boundingObject USE fcam
      physics Physics {
      }
      fieldOfView 1
      width 640
      height 480
    }
    DEF castorFront Solid {
      translation 0 -0.15 -0.051
      children [
        DEF castor Shape {
          appearance PBRAppearance {
          }
          geometry Sphere {
            radius 0.005
          }
          castShadows FALSE
        }
      ]
      boundingObject USE castor
      physics Physics {
      }
    }
    DEF castorBack Solid {
      translation 0 0.149 -0.051
      children [
        DEF castor Shape {
          appearance PBRAppearance {
          }
          geometry Sphere {
            radius 0.005
          }
          castShadows FALSE
        }
      ]
      name "solid(1)"
      boundingObject USE castor
      physics Physics {
      }
    }
    HingeJoint {
      jointParameters HingeJointParameters {
        position 343.80418634508203
        anchor 0.181 0 -0.03
      }
      device [
        PositionSensor {
          name "leftEncoder"
        }
        RotationalMotor {
          name "leftMotor"
          maxVelocity 100
          maxTorque 100
        }
      ]
      endPoint Solid {
        translation 0.181 0 -0.03
        rotation 0.7024184765199136 0.11494756637542985 0.7024210566517846 2.9127029325907516
        children [
          DEF leftWheel Shape {
            appearance PBRAppearance {
              baseColorMap ImageTexture {
                url [
                  "../assets/wheel.jpg"
                ]
              }
            }
            geometry Cylinder {
              height 0.01
              radius 0.03
            }
            castShadows FALSE
          }
        ]
        name "leftWheel"
        boundingObject USE leftWheel
        physics Physics {
        }
      }
    }
    HingeJoint {
      jointParameters HingeJointParameters {
        position 339.9401848066847
        anchor -0.181 0 -0.03
      }
      device [
        DEF rightEncoder PositionSensor {
          name "rightEncoder"
        }
        DEF rightMotor RotationalMotor {
          name "rightMotor"
          maxVelocity 100
          maxTorque 100
        }
      ]
      endPoint Solid {
        translation -0.181 0 -0.03
        rotation 0.30343074526577174 0.9032490745335671 0.30343185755901286 1.672381753801883
        children [
          DEF rightWheel Shape {
            appearance PBRAppearance {
              baseColorMap ImageTexture {
                url [
                  "../assets/wheel.jpg"
                ]
                filtering 5
              }
              textureTransform TextureTransform {
              }
            }
            geometry Cylinder {
              height 0.01
              radius 0.03
            }
            castShadows FALSE
          }
        ]
        name "rightWheel"
        boundingObject USE rightWheel
        physics Physics {
        }
      }
    }
    DEF body Shape {
      appearance PBRAppearance {
        metalness 0.5
      }
      geometry Cylinder {
        height 0.1
        radius 0.177
      }
      castShadows FALSE
    }
  ]
  boundingObject USE body
  physics Physics {
    centerOfMass [
      0 0 0
    ]
  }
  controller "bbAlr8"
  cpuConsumption 20
}
