#VRML_SIM R2025a utf8

EXTERNPROTO "https://raw.githubusercontent.com/cyberbotics/webots/R2025a/projects/objects/floors/protos/RectangleArena.proto"
EXTERNPROTO "https://raw.githubusercontent.com/cyberbotics/webots/R2025a/projects/objects/apartment_structure/protos/Wall.proto"
EXTERNPROTO "https://raw.githubusercontent.com/cyberbotics/webots/R2025a/projects/appearances/protos/BrushedAluminium.proto"
EXTERNPROTO "https://raw.githubusercontent.com/cyberbotics/webots/R2025a/projects/objects/backgrounds/protos/TexturedBackground.proto"
EXTERNPROTO "https://raw.githubusercontent.com/cyberbotics/webots/R2025a/projects/objects/backgrounds/protos/TexturedBackgroundLight.proto"
EXTERNPROTO "https://raw.githubusercontent.com/cyberbotics/webots/R2025a/projects/appearances/protos/Roughcast.proto"

WorldInfo {
}
Viewpoint {
  orientation -0.6702874121816393 0.04897726767508927 0.7404836340675759 3.033489406495255
  position 0.9222431835434807 -0.35553189219053377 10.192571940111163
}
TexturedBackground {
}
TexturedBackgroundLight {
}
DirectionalLight {
  direction 0.3 -0.5 -0.7
  intensity 1.5
}
RectangleArena {
  floorSize 3.048 3.048
  floorAppearance PBRAppearance {
    baseColor 0 0 0
    roughness 1
    metalness 0
  }
  wallHeight 0.6096
  wallAppearance BrushedAluminium {
    IBLStrength 0
  }
}
Wall {
  translation 1.52 -0.78 0
  name "wall(2)"
  size 0.01 0.4 0.4
  appearance Roughcast {
    colorOverride 1 0 0
    textureTransform TextureTransform {
      scale 2.4 1
    }
  }
}
Wall {
  translation -0.16 -0.74 0
  rotation 0 0 1 1.5708
  name "wall(8)"
  size 0.1 0.375 0.125
}
Wall {
  translation -0.87 0.19 0
  name "wall(9)"
  size 0.125 0.375 0.105
}
Wall {
  translation 0.97 -0.1 0
  name "wall(12)"
  size 0.125 0.375 0.105
}
Wall {
  translation 0.84 -1.18 0
  rotation 0 0 1 -1.5707953071795862
  name "wall(10)"
  size 0.1 0.375 0.125
}
Wall {
  translation 1.52 -0.78 0
  rotation 0 1 0 -1.5707953071795862
  name "wall(7)"
  size 0.001 0.4 0.4
  appearance Roughcast {
    colorOverride 1 0 0
    textureTransform TextureTransform {
      scale 2.4 1
    }
  }
}
Wall {
  translation 1.52 0.61 0
  name "wall(3)"
  size 0.01 0.4 0.4
  appearance Roughcast {
    colorOverride 0 1 1
    textureTransform TextureTransform {
      scale 2.4 1
    }
  }
}
Wall {
  translation 1.52 0.61 0
  rotation 0 1 0 -1.5707953071795862
  name "wall(6)"
  size 0.001 0.4 0.4
  appearance Roughcast {
    colorOverride 0 1 1
    textureTransform TextureTransform {
      scale 2.4 1
    }
  }
}
Wall {
  translation 0.26 1.31 1.28473e-06
  rotation 0 1 0 -1.5707953071795862
  name "wall(11)"
  size 0.001 0.4 0.4
}
Wall {
  translation -1.52 -0.78 0
  size 0.01 0.4 0.4
  appearance Roughcast {
    colorOverride 0 1 0
    textureTransform TextureTransform {
      scale 2.4 1
    }
  }
}
Wall {
  translation -1.52 -0.78 0
  rotation 0 1 0 1.5708
  name "wall(5)"
  size 0.001 0.4 0.4
  appearance Roughcast {
    colorOverride 0 1 0
    textureTransform TextureTransform {
      scale 2.4 1
    }
  }
}
Wall {
  translation -1.52 0.61 0
  name "wall(1)"
  size 0.01 0.4 0.4
  appearance Roughcast {
    colorOverride 1 1 0
    textureTransform TextureTransform {
      scale 2.4 1
    }
  }
}
Wall {
  translation -1.52 0.61 0
  rotation 0 1 0 1.5708
  name "wall(4)"
  size 0.001 0.4 0.4
  appearance Roughcast {
    colorOverride 1 1 0
    textureTransform TextureTransform {
      scale 2.4 1
    }
  }
}
Solid {
  translation 0.6499342831149266 -0.499571373976642 0.037334481803105425
  rotation -0.5937580369662686 0.5430495254356886 0.5937580369662687 2.146610058666204
  children [
    DEF rbox Shape {
      appearance PBRAppearance {
        baseColor 1 0 0
        roughness 0.5
        metalness 0
      }
      geometry Box {
        size 0.075 0.075 0.075
      }
    }
  ]
  name "red_box"
  boundingObject USE rbox
  physics Physics {
  }
  linearVelocity -2.596148788006024e-17 3.438226912773927e-17 -1.998396770364552e-07
  angularVelocity -8.421247238638237e-16 -1.1228329651517619e-15 3.183783335541694e-18
}
Solid {
  translation -0.6317526852789814 -0.35681627780665615 0.037334481803105425
  rotation 4.841951016538541e-17 8.437815376981852e-17 1 1.9423900719307867
  children [
    DEF gbox Shape {
      appearance PBRAppearance {
        baseColor 0 1 0
        roughness 0.5
        metalness 0
      }
      geometry Box {
        size 0.075 0.075 0.075
      }
    }
  ]
  name "green_box"
  boundingObject USE gbox
  physics Physics {
  }
  linearVelocity -3.4511878666237646e-17 -1.0551302008634698e-18 -1.998396770364552e-07
  angularVelocity -2.9582283945787943e-31 -2.8070824128794096e-16 5.537061957318058e-17
}
Solid {
  translation -0.2038933197209632 -1.1003322495157752 0.03733448180310543
  rotation 0.9992644393109119 -0.03834814635218884 -9.503493338360144e-17 3.141592653589793
  children [
    DEF wbox Shape {
      appearance PBRAppearance {
        roughness 0.5
        metalness 0
      }
      geometry Box {
        size 0.075 0.075 0.075
      }
    }
  ]
  name "white_box"
  boundingObject USE wbox
  physics Physics {
  }
  linearVelocity 9.522071727352591e-17 1.893651347118515e-17 -1.9983967710375763e-07
  angularVelocity 5.614164825758807e-16 3.3684988954552903e-15 -3.1808896840050336e-16
}
Solid {
  translation -0.6045196699429661 0.5854050428297629 0.037334481803105425
  rotation 6.32724180698152e-17 1.0800145949571553e-17 1 1.0168422449409296
  children [
    DEF ybox Shape {
      appearance PBRAppearance {
        baseColor 1 1 0
        roughness 0.5
        metalness 0
      }
      geometry Box {
        size 0.075 0.075 0.075
      }
    }
  ]
  name "yellow_box"
  boundingObject USE ybox
  physics Physics {
  }
  linearVelocity 5.4933281299861637e-17 -4.672622432935366e-18 -1.9983967710378288e-07
  angularVelocity 1.4035412064397068e-16 2.105311809659555e-15 -4.1758936459420247e-16
}
Solid {
  translation 0.5971829158325305 0.7172612756261855 0.037334481803105425
  rotation 1.3079226355573296e-16 -3.98595863667657e-17 -1 0.325359666289761
  children [
    DEF bbox Shape {
      appearance PBRAppearance {
        baseColor 0 1 1
        roughness 0.5
        metalness 0
      }
      geometry Box {
        size 0.075 0.075 0.075
      }
    }
  ]
  name "cyan_box"
  boundingObject USE bbox
  physics Physics {
  }
  linearVelocity 6.196846664787393e-17 -2.1667243379944357e-17 -1.998396771037849e-07
  angularVelocity 1.4035412064397044e-15 2.8070824128794096e-16 -9.034402392680278e-17
}
DEF BBAlr8 Robot {
  translation 0.14527037399406517 1.239168280856139 0.05596361296788744
  rotation 0.07355957756543931 0.0010789414887741528 0.9972902408194206 0.12242251404738272
  children [
    Display {
      children [
        DEF disp Shape {
          geometry Box {
            size 0.01 0.01 0.01
          }
        }
      ]
      boundingObject USE disp
      physics Physics {
      }
      width 640
      height 480
    }
    DEF gyro Gyro {
      children [
        DEF gyroS Shape {
          geometry Sphere {
            radius 0.01
          }
        }
      ]
      boundingObject USE gyroS
      physics Physics {
      }
    }
    Solid {
      translation 0.11 -0.2 0
      children [
        DEF leftArm Shape {
          appearance PBRAppearance {
            baseColor 0 0 0
          }
          geometry Box {
            size 0.02 0.15 0.09
          }
        }
      ]
      name "solid(2)"
      boundingObject USE leftArm
      physics Physics {
      }
    }
    Solid {
      translation -0.11 -0.2 0
      children [
        DEF rightArm Shape {
          appearance PBRAppearance {
            baseColor 0 0 0
          }
          geometry Box {
            size 0.02 0.15 0.09
          }
        }
      ]
      name "solid(3)"
      boundingObject USE rightArm
      physics Physics {
      }
    }
    DEF frontCam Camera {
      translation -0.00497507 -0.0650495 0.090495
      rotation 0 0 -1 1.5708
      children [
        DEF fcam Shape {
          appearance PBRAppearance {
            baseColor 1 0 0
          }
          geometry Capsule {
            height 0.012
            radius 0.04
          }
          castShadows FALSE
        }
      ]
      name "fcam"
      boundingObject USE fcam
      physics Physics {
      }
      fieldOfView 1
      width 640
      height 480
    }
    DEF castorFront Solid {
      translation 0 -0.15 -0.051
      children [
        DEF castor Shape {
          appearance PBRAppearance {
          }
          geometry Sphere {
            radius 0.005
          }
          castShadows FALSE
        }
      ]
      boundingObject USE castor
      physics Physics {
      }
    }
    DEF castorBack Solid {
      translation 0 0.149 -0.051
      children [
        DEF castor Shape {
          appearance PBRAppearance {
          }
          geometry Sphere {
            radius 0.005
          }
          castShadows FALSE
        }
      ]
      name "solid(1)"
      boundingObject USE castor
      physics Physics {
      }
    }
    HingeJoint {
      jointParameters HingeJointParameters {
        position 2738.368320385667
        anchor 0.181 0 -0.03
      }
      device [
        PositionSensor {
          name "leftEncoder"
        }
        RotationalMotor {
          name "leftMotor"
          maxVelocity 100
          maxTorque 100
        }
      ]
      endPoint Solid {
        translation 0.18160993891107124 -5.941872108108079e-06 -0.029997760003103228
        rotation 0.702930091483122 -0.11857691888080733 0.7013050697066607 3.3940688343728382
        children [
          DEF leftWheel Shape {
            appearance PBRAppearance {
              baseColorMap ImageTexture {
                url [
                  "../assets/wheel.jpg"
                ]
              }
            }
            geometry Cylinder {
              height 0.01
              radius 0.03
            }
            castShadows FALSE
          }
        ]
        name "leftWheel"
        boundingObject USE leftWheel
        physics Physics {
        }
        linearVelocity 3.630436517342303e-10 4.5902029731065255e-09 -5.95288609622387e-09
        angularVelocity -1.8278376665667937e-07 -8.123526224709347e-09 3.7097428296857736e-10
      }
    }
    HingeJoint {
      jointParameters HingeJointParameters {
        position 2748.6810303980765
        anchor -0.181 0 -0.03
      }
      device [
        DEF rightEncoder PositionSensor {
          name "rightEncoder"
        }
        DEF rightMotor RotationalMotor {
          name "rightMotor"
          maxVelocity 100
          maxTorque 100
        }
      ]
      endPoint Solid {
        translation -0.1815837872808982 -9.7787274542074e-05 -0.029850359155934543
        rotation -0.7083799452030379 -0.07767196809078762 -0.7015446661525157 3.286767554073523
        children [
          DEF rightWheel Shape {
            appearance PBRAppearance {
              baseColorMap ImageTexture {
                url [
                  "../assets/wheel.jpg"
                ]
                filtering 5
              }
              textureTransform TextureTransform {
              }
            }
            geometry Cylinder {
              height 0.01
              radius 0.03
            }
            castShadows FALSE
          }
        ]
        name "rightWheel"
        boundingObject USE rightWheel
        physics Physics {
        }
        linearVelocity -1.3338349045879743e-09 6.181004356736512e-09 -8.273284597734175e-10
        angularVelocity -2.2816390221998607e-07 -1.3645239871954138e-08 3.5500010689612685e-10
      }
    }
    DEF body Shape {
      appearance PBRAppearance {
        metalness 0.5
      }
      geometry Cylinder {
        height 0.1
        radius 0.177
      }
      castShadows FALSE
    }
  ]
  boundingObject USE body
  physics Physics {
    centerOfMass [
      0 0 0
    ]
  }
  controller "bbAlr8"
  cpuConsumption 20
  linearVelocity 1.1620305828425358e-10 1.3863838421778578e-08 -2.4285100625118028e-09
  angularVelocity -1.80025506000389e-07 -7.796979730335566e-09 3.739749209196964e-10
}
