#VRML_SIM R2025a utf8

EXTERNPROTO "https://raw.githubusercontent.com/cyberbotics/webots/R2025a/projects/objects/floors/protos/RectangleArena.proto"
EXTERNPROTO "https://raw.githubusercontent.com/cyberbotics/webots/R2025a/projects/objects/apartment_structure/protos/Wall.proto"
EXTERNPROTO "https://raw.githubusercontent.com/cyberbotics/webots/R2025a/projects/appearances/protos/BrushedAluminium.proto"
EXTERNPROTO "https://raw.githubusercontent.com/cyberbotics/webots/R2025a/projects/objects/backgrounds/protos/TexturedBackground.proto"
EXTERNPROTO "https://raw.githubusercontent.com/cyberbotics/webots/R2025a/projects/objects/backgrounds/protos/TexturedBackgroundLight.proto"
EXTERNPROTO "https://raw.githubusercontent.com/cyberbotics/webots/R2025a/projects/appearances/protos/Roughcast.proto"

WorldInfo {
}
Viewpoint {
  orientation -0.5547674779128806 -0.5296310291870435 0.6416572436842387 4.240839693712428
  position -0.3328134290624267 1.701894147260642 9.336940796831724
}
TexturedBackground {
}
TexturedBackgroundLight {
}
DirectionalLight {
  direction 0.3 -0.5 -0.7
  intensity 1.5
}
RectangleArena {
  floorSize 3.048 3.048
  floorAppearance PBRAppearance {
    baseColor 0 0 0
    roughness 1
    metalness 0
  }
  wallHeight 0.6096
  wallAppearance BrushedAluminium {
    IBLStrength 0
  }
}
Wall {
  translation 1.52 -0.78 0
  name "wall(2)"
  size 0.01 0.4 0.4
  appearance Roughcast {
    colorOverride 1 0 0
    textureTransform TextureTransform {
      scale 2.4 1
    }
  }
}
Wall {
  translation -0.16 -0.74 0
  rotation 0 0 1 1.5708
  name "wall(8)"
  size 0.1 0.375 0.125
}
Wall {
  translation -0.87 0.19 0
  name "wall(9)"
  size 0.125 0.375 0.105
}
Wall {
  translation 0.97 -0.1 0
  name "wall(12)"
  size 0.125 0.375 0.105
}
Wall {
  translation 0.84 -1.18 0
  rotation 0 0 1 -1.5707953071795862
  name "wall(10)"
  size 0.1 0.375 0.125
}
Wall {
  translation 1.52 -0.78 0
  rotation 0 1 0 -1.5707953071795862
  name "wall(7)"
  size 0.001 0.4 0.4
  appearance Roughcast {
    colorOverride 1 0 0
    textureTransform TextureTransform {
      scale 2.4 1
    }
  }
}
Wall {
  translation 1.52 0.61 0
  name "wall(3)"
  size 0.01 0.4 0.4
  appearance Roughcast {
    colorOverride 0 1 1
    textureTransform TextureTransform {
      scale 2.4 1
    }
  }
}
Wall {
  translation 1.52 0.61 0
  rotation 0 1 0 -1.5707953071795862
  name "wall(6)"
  size 0.001 0.4 0.4
  appearance Roughcast {
    colorOverride 0 1 1
    textureTransform TextureTransform {
      scale 2.4 1
    }
  }
}
Wall {
  translation 0.26 1.31 1.28473e-06
  rotation 0 1 0 -1.5707953071795862
  name "wall(11)"
  size 0.001 0.4 0.4
}
Wall {
  translation -1.52 -0.78 0
  size 0.01 0.4 0.4
  appearance Roughcast {
    colorOverride 0 1 0
    textureTransform TextureTransform {
      scale 2.4 1
    }
  }
}
Wall {
  translation -1.52 -0.78 0
  rotation 0 1 0 1.5708
  name "wall(5)"
  size 0.001 0.4 0.4
  appearance Roughcast {
    colorOverride 0 1 0
    textureTransform TextureTransform {
      scale 2.4 1
    }
  }
}
Wall {
  translation -1.52 0.61 0
  name "wall(1)"
  size 0.01 0.4 0.4
  appearance Roughcast {
    colorOverride 1 1 0
    textureTransform TextureTransform {
      scale 2.4 1
    }
  }
}
Wall {
  translation -1.52 0.61 0
  rotation 0 1 0 1.5708
  name "wall(4)"
  size 0.001 0.4 0.4
  appearance Roughcast {
    colorOverride 1 1 0
    textureTransform TextureTransform {
      scale 2.4 1
    }
  }
}
Solid {
  translation 0.477324 -0.786743 0.03660302074033122
  rotation 7.843706095538847e-17 1.5863604802531298e-16 1 0.523599
  children [
    DEF rbox Shape {
      appearance PBRAppearance {
        baseColor 1 0 0
        roughness 0.5
        metalness 0
      }
      geometry Box {
        size 0.075 0.075 0.075
      }
    }
  ]
  name "red_box"
  boundingObject USE rbox
  physics Physics {
  }
  linearVelocity -1.054072592587047e-16 9.63060298293845e-18 0.005720237663288605
  angularVelocity -1.0526559048297788e-15 -1.824603568371614e-15 3.9686676143337897e-16
}
Solid {
  translation -0.8892320582121507 -1.18984591775451 0.0366031042580257
  rotation 0.9369194995219867 -0.2471657858760695 -0.24716578587606952 1.6359081838648986
  children [
    DEF gbox Shape {
      appearance PBRAppearance {
        baseColor 0 1 0
        roughness 0.5
        metalness 0
      }
      geometry Box {
        size 0.075 0.075 0.075
      }
    }
  ]
  name "green_box"
  boundingObject USE gbox
  physics Physics {
  }
  linearVelocity 6.058167362692724e-17 -5.247069914949091e-17 0.005719584507876823
  angularVelocity 1.9649576890155867e-15 9.82478844507792e-16 -1.0116586923869895e-16
}
Solid {
  translation -0.006073784898119729 0.11714769126389706 0.03727177606148995
  rotation 8.66765377148724e-17 -2.64320467647584e-16 -1 1.0806630833727853
  children [
    DEF wbox Shape {
      appearance PBRAppearance {
        roughness 0.5
        metalness 0
      }
      geometry Box {
        size 0.075 0.075 0.075
      }
    }
  ]
  name "white_box"
  boundingObject USE wbox
  physics Physics {
  }
  linearVelocity -3.977629483602488e-17 2.7394294742050293e-17 0.0004901943784758735
  angularVelocity -6.781025053641994e-16 1.0993173116614732e-17 -7.170454507860238e-17
}
Solid {
  translation -0.5976480652747647 0.5781719229683006 0.036603104258025716
  rotation -1.9782491359856612e-16 -9.072210381561024e-17 1 0.8747069927423238
  children [
    DEF ybox Shape {
      appearance PBRAppearance {
        baseColor 1 1 0
        roughness 0.5
        metalness 0
      }
      geometry Box {
        size 0.075 0.075 0.075
      }
    }
  ]
  name "yellow_box"
  boundingObject USE ybox
  physics Physics {
  }
  linearVelocity 3.889036655537832e-17 -6.318584764107947e-17 0.005719584507876742
  angularVelocity 2.8070824128794147e-15 5.263279524148892e-16 3.7709384877628896e-16
}
Solid {
  translation 0.53 0.38 0.03660310425802572
  rotation -0.97128949313127 -0.19657049265751875 -0.13400284306379834 3.8842371811800224e-16
  children [
    DEF bbox Shape {
      appearance PBRAppearance {
        baseColor 0 1 1
        roughness 0.5
        metalness 0
      }
      geometry Box {
        size 0.075 0.075 0.075
      }
    }
  ]
  name "cyan_box"
  boundingObject USE bbox
  physics Physics {
  }
  linearVelocity 8.13884836910339e-17 -3.7417419487825644e-17 0.0057195845078766416
  angularVelocity 8.421247238638227e-16 1.6842494477276467e-15 1.3598057372497234e-16
}
DEF BBAlr8 Robot {
  translation 0.0646157 1.33274 0.0594643
  children [
    Solid {
      translation 0.11 -0.2 0
      children [
        DEF leftArm Shape {
          appearance PBRAppearance {
            baseColor 0 0 0
          }
          geometry Box {
            size 0.02 0.15 0.09
          }
        }
      ]
      name "solid(2)"
      boundingObject USE leftArm
      physics Physics {
      }
    }
    Solid {
      translation -0.11 -0.2 0
      children [
        DEF rightArm Shape {
          appearance PBRAppearance {
            baseColor 0 0 0
          }
          geometry Box {
            size 0.02 0.15 0.09
          }
        }
      ]
      name "solid(3)"
      boundingObject USE rightArm
      physics Physics {
      }
    }
    DEF frontCam Camera {
      translation -0.00497507 -0.0650495 0.090495
      rotation 0 0 -1 1.5708
      children [
        DEF fcam Shape {
          appearance PBRAppearance {
            baseColor 1 0 0
          }
          geometry Capsule {
            height 0.012
            radius 0.04
          }
          castShadows FALSE
        }
      ]
      name "fcam"
      boundingObject USE fcam
      physics Physics {
      }
      fieldOfView 1
      width 640
      height 480
    }
    DEF castorFront Solid {
      translation 0 -0.15 -0.051
      children [
        DEF castor Shape {
          appearance PBRAppearance {
          }
          geometry Sphere {
            radius 0.005
          }
          castShadows FALSE
        }
      ]
      boundingObject USE castor
      physics Physics {
      }
    }
    DEF castorBack Solid {
      translation 0 0.149 -0.051
      children [
        DEF castor Shape {
          appearance PBRAppearance {
          }
          geometry Sphere {
            radius 0.005
          }
          castShadows FALSE
        }
      ]
      name "solid(1)"
      boundingObject USE castor
      physics Physics {
      }
    }
    HingeJoint {
      jointParameters HingeJointParameters {
        position 362.8285702070544
        anchor 0.181 0 -0.03
      }
      device [
        PositionSensor {
          name "leftEncoder"
        }
        RotationalMotor {
          name "leftMotor"
          maxVelocity 100
          maxTorque 100
        }
      ]
      endPoint Solid {
        translation 0.181 0 -0.03
        rotation -0.7061149760371984 -0.05291141947106525 -0.7061175697470949 3.247316515943622
        children [
          DEF leftWheel Shape {
            appearance PBRAppearance {
              baseColorMap ImageTexture {
                url [
                  "../assets/wheel.jpg"
                ]
              }
            }
            geometry Cylinder {
              height 0.01
              radius 0.03
            }
            castShadows FALSE
          }
        ]
        name "leftWheel"
        boundingObject USE leftWheel
        physics Physics {
        }
      }
    }
    HingeJoint {
      jointParameters HingeJointParameters {
        position 355.6339873427084
        anchor -0.181 0 -0.03
      }
      device [
        DEF rightEncoder PositionSensor {
          name "rightEncoder"
        }
        DEF rightMotor RotationalMotor {
          name "rightMotor"
          maxVelocity 100
          maxTorque 100
        }
      ]
      endPoint Solid {
        translation -0.181 0 -0.03
        rotation 0.6888137172104949 -0.2259819626623574 0.6888162422111788 3.5860888608453676
        children [
          DEF rightWheel Shape {
            appearance PBRAppearance {
              baseColorMap ImageTexture {
                url [
                  "../assets/wheel.jpg"
                ]
                filtering 5
              }
              textureTransform TextureTransform {
              }
            }
            geometry Cylinder {
              height 0.01
              radius 0.03
            }
            castShadows FALSE
          }
        ]
        name "rightWheel"
        boundingObject USE rightWheel
        physics Physics {
        }
      }
    }
    DEF body Shape {
      appearance PBRAppearance {
        metalness 0.5
      }
      geometry Cylinder {
        height 0.1
        radius 0.177
      }
      castShadows FALSE
    }
  ]
  boundingObject USE body
  physics Physics {
    centerOfMass [
      0 0 0
    ]
  }
  controller "bbAlr8"
  cpuConsumption 20
}
