#VRML_SIM R2025a utf8

EXTERNPROTO "https://raw.githubusercontent.com/cyberbotics/webots/R2025a/projects/objects/floors/protos/RectangleArena.proto"
EXTERNPROTO "https://raw.githubusercontent.com/cyberbotics/webots/R2025a/projects/objects/apartment_structure/protos/Wall.proto"
EXTERNPROTO "https://raw.githubusercontent.com/cyberbotics/webots/R2025a/projects/appearances/protos/BrushedAluminium.proto"
EXTERNPROTO "https://raw.githubusercontent.com/cyberbotics/webots/R2025a/projects/objects/backgrounds/protos/TexturedBackground.proto"
EXTERNPROTO "https://raw.githubusercontent.com/cyberbotics/webots/R2025a/projects/objects/backgrounds/protos/TexturedBackgroundLight.proto"
EXTERNPROTO "https://raw.githubusercontent.com/cyberbotics/webots/R2025a/projects/appearances/protos/Roughcast.proto"

WorldInfo {
}
Viewpoint {
  orientation -0.36375496700451254 0.4800085795124893 0.798294486749062 1.5187817952129992
  position -2.5028297957576067 -5.327325193785998 6.571693281007842
}
TexturedBackground {
}
TexturedBackgroundLight {
}
DirectionalLight {
  direction 0.3 -0.5 -0.7
  intensity 1.5
}
RectangleArena {
  floorSize 3.048 3.048
  floorAppearance PBRAppearance {
    baseColor 0 0 0
    roughness 1
    metalness 0
  }
  wallHeight 0.6096
  wallAppearance BrushedAluminium {
    IBLStrength 0
  }
}
Wall {
  translation 1.52 -0.78 0
  name "wall(2)"
  size 0.01 0.4 0.4
  appearance Roughcast {
    colorOverride 1 0 0
    textureTransform TextureTransform {
      scale 2.4 1
    }
  }
}
Wall {
  translation -0.16 -1.28 0
  rotation 0 0 1 1.5708
  name "wall(8)"
  size 0.1 0.375 0.125
}
Wall {
  translation -0.87 0.19 0
  name "wall(9)"
  size 0.125 0.375 0.105
}
Wall {
  translation 0.97 -0.1 0
  name "wall(12)"
  size 0.125 0.375 0.105
}
Wall {
  translation 0.84 -1.18 0
  rotation 0 0 1 -1.5707953071795862
  name "wall(10)"
  size 0.1 0.375 0.125
}
Wall {
  translation 1.52 -0.78 0
  rotation 0 1 0 -1.5707953071795862
  name "wall(7)"
  size 0.001 0.4 0.4
  appearance Roughcast {
    colorOverride 1 0 0
    textureTransform TextureTransform {
      scale 2.4 1
    }
  }
}
Wall {
  translation 1.52 0.61 0
  name "wall(3)"
  size 0.01 0.4 0.4
  appearance Roughcast {
    colorOverride 0 1 1
    textureTransform TextureTransform {
      scale 2.4 1
    }
  }
}
Wall {
  translation 1.52 0.61 0
  rotation 0 1 0 -1.5707953071795862
  name "wall(6)"
  size 0.001 0.4 0.4
  appearance Roughcast {
    colorOverride 0 1 1
    textureTransform TextureTransform {
      scale 2.4 1
    }
  }
}
Wall {
  translation 0.26 1.31 1.28473e-06
  rotation 0 1 0 -1.5707953071795862
  name "wall(11)"
  size 0.001 0.4 0.4
}
Wall {
  translation -1.52 -0.78 0
  size 0.01 0.4 0.4
  appearance Roughcast {
    colorOverride 0 1 0
    textureTransform TextureTransform {
      scale 2.4 1
    }
  }
}
Wall {
  translation -1.52 -0.78 0
  rotation 0 1 0 1.5708
  name "wall(5)"
  size 0.001 0.4 0.4
  appearance Roughcast {
    colorOverride 0 1 0
    textureTransform TextureTransform {
      scale 2.4 1
    }
  }
}
Wall {
  translation -1.52 0.61 0
  name "wall(1)"
  size 0.01 0.4 0.4
  appearance Roughcast {
    colorOverride 1 1 0
    textureTransform TextureTransform {
      scale 2.4 1
    }
  }
}
Wall {
  translation -1.52 0.61 0
  rotation 0 1 0 1.5708
  name "wall(4)"
  size 0.001 0.4 0.4
  appearance Roughcast {
    colorOverride 1 1 0
    textureTransform TextureTransform {
      scale 2.4 1
    }
  }
}
Solid {
  translation 0.3160178830336076 -0.9560296309371286 0.03733448180310544
  rotation 3.174651742859943e-17 -4.040278965002515e-17 -1 1.4707225602854175
  children [
    DEF rbox Shape {
      appearance PBRAppearance {
        baseColor 1 0 0
        roughness 0.5
        metalness 0
      }
      geometry Box {
        size 0.075 0.075 0.075
      }
    }
  ]
  name "red_box"
  boundingObject USE rbox
  physics Physics {
  }
  linearVelocity 8.707741078899809e-17 5.802592582650177e-17 -1.9983967710378304e-07
  angularVelocity -1.4035412064397032e-15 2.807082412879408e-15 -5.549760918746746e-17
}
Solid {
  translation -0.6698755787164241 -0.23092883593636268 0.03733448180310543
  rotation 5.444129306176644e-18 1.231589181519777e-17 1 1.7779103020404803
  children [
    DEF gbox Shape {
      appearance PBRAppearance {
        baseColor 0 1 0
        roughness 0.5
        metalness 0
      }
      geometry Box {
        size 0.075 0.075 0.075
      }
    }
  ]
  name "green_box"
  boundingObject USE gbox
  physics Physics {
  }
  linearVelocity -5.66648185941103e-18 1.9918835252730476e-17 -1.9983967710385308e-07
  angularVelocity 1.064962222048366e-29 1.1438483125704671e-29 4.650060826727876e-16
}
Solid {
  translation -0.19552489173182752 -1.1056102165180632 0.03733448180310544
  rotation 0.9999132912430965 0.013168522901167786 -9.693503425933538e-18 3.141592653589793
  children [
    DEF wbox Shape {
      appearance PBRAppearance {
        roughness 0.5
        metalness 0
      }
      geometry Box {
        size 0.075 0.075 0.075
      }
    }
  ]
  name "white_box"
  boundingObject USE wbox
  physics Physics {
  }
  linearVelocity 4.029035917577638e-17 -3.5786250066874545e-17 -1.9983967717126113e-07
  angularVelocity 1.4035412064397052e-15 1.1228329651517638e-15 -8.758034264975462e-17
}
Solid {
  translation -0.7276629379464747 0.7329555131833626 0.03733448180310544
  rotation -5.708260173554081e-17 -9.678058867738088e-17 1 1.2921498387510835
  children [
    DEF ybox Shape {
      appearance PBRAppearance {
        baseColor 1 1 0
        roughness 0.5
        metalness 0
      }
      geometry Box {
        size 0.075 0.075 0.075
      }
    }
  ]
  name "yellow_box"
  boundingObject USE ybox
  physics Physics {
  }
  linearVelocity -1.3452105094390156e-17 -5.900230884447932e-17 -1.998396773059356e-07
  angularVelocity 1.6842494477276465e-15 -2.2456659303035277e-15 -2.4604977703233704e-16
}
Solid {
  translation 0.3538308794342245 0.3055841423136196 0.03733448180310543
  rotation 3.387509953813567e-16 -2.0342317915359345e-16 -1 0.4663911557286902
  children [
    DEF bbox Shape {
      appearance PBRAppearance {
        baseColor 0 1 1
        roughness 0.5
        metalness 0
      }
      geometry Box {
        size 0.075 0.075 0.075
      }
    }
  ]
  name "cyan_box"
  boundingObject USE bbox
  physics Physics {
  }
  linearVelocity -5.346897385805706e-17 -7.319314494839507e-17 -1.9983967717115292e-07
  angularVelocity 3.3684988954552903e-15 -1.4035412064397052e-15 1.7509951259900186e-16
}
DEF BBAlr8 Robot {
  translation -0.1457665276914964 0.6658845469099148 0.05596361256855333
  rotation 0.003956944809219043 -0.0046887931951039635 -0.9999811787259552 1.646948347924885
  children [
    Display {
      children [
        DEF disp Shape {
          geometry Box {
            size 0.01 0.01 0.01
          }
        }
      ]
      boundingObject USE disp
      physics Physics {
      }
      width 640
      height 480
    }
    DEF gyro Gyro {
      children [
        DEF gyroS Shape {
          geometry Sphere {
            radius 0.01
          }
        }
      ]
      boundingObject USE gyroS
      physics Physics {
      }
    }
    Solid {
      translation 0.11 -0.2 0
      children [
        DEF leftArm Shape {
          appearance PBRAppearance {
            baseColor 0 0 0
          }
          geometry Box {
            size 0.02 0.15 0.09
          }
        }
      ]
      name "solid(2)"
      boundingObject USE leftArm
      physics Physics {
      }
    }
    Solid {
      translation -0.11 -0.2 0
      children [
        DEF rightArm Shape {
          appearance PBRAppearance {
            baseColor 0 0 0
          }
          geometry Box {
            size 0.02 0.15 0.09
          }
        }
      ]
      name "solid(3)"
      boundingObject USE rightArm
      physics Physics {
      }
    }
    DEF frontCam Camera {
      translation -0.00497507 -0.0650495 0.090495
      rotation 0 0 -1 1.5708
      children [
        DEF fcam Shape {
          appearance PBRAppearance {
            baseColor 1 0 0
          }
          geometry Capsule {
            height 0.012
            radius 0.04
          }
          castShadows FALSE
        }
      ]
      name "fcam"
      boundingObject USE fcam
      physics Physics {
      }
      fieldOfView 1
      width 640
      height 480
    }
    DEF castorFront Solid {
      translation 0 -0.15 -0.051
      children [
        DEF castor Shape {
          appearance PBRAppearance {
          }
          geometry Sphere {
            radius 0.005
          }
          castShadows FALSE
        }
      ]
      boundingObject USE castor
      physics Physics {
      }
    }
    DEF castorBack Solid {
      translation 0 0.149 -0.051
      children [
        DEF castor Shape {
          appearance PBRAppearance {
          }
          geometry Sphere {
            radius 0.005
          }
          castShadows FALSE
        }
      ]
      name "solid(1)"
      boundingObject USE castor
      physics Physics {
      }
    }
    HingeJoint {
      jointParameters HingeJointParameters {
        position 2738.368639326328
        anchor 0.181 0 -0.03
      }
      device [
        PositionSensor {
          name "leftEncoder"
        }
        RotationalMotor {
          name "leftMotor"
          maxVelocity 100
          maxTorque 100
        }
      ]
      endPoint Solid {
        translation 0.18160993891107124 -5.9425862319936935e-06 -0.0299977618983217
        rotation 0.7029198481236494 -0.1186904440066202 0.7012961326111368 3.3942930257273782
        children [
          DEF leftWheel Shape {
            appearance PBRAppearance {
              baseColorMap ImageTexture {
                url [
                  "../assets/wheel.jpg"
                ]
              }
            }
            geometry Cylinder {
              height 0.01
              radius 0.03
            }
            castShadows FALSE
          }
        ]
        name "leftWheel"
        boundingObject USE leftWheel
        physics Physics {
        }
        linearVelocity 6.236510517179133e-12 -9.941865965611412e-11 1.809376838542536e-14
        angularVelocity 2.0298804892915937e-10 2.8370698592796144e-09 -3.299746680219302e-09
      }
    }
    HingeJoint {
      jointParameters HingeJointParameters {
        position 2748.6810247614044
        anchor -0.181 0 -0.03
      }
      device [
        DEF rightEncoder PositionSensor {
          name "rightEncoder"
        }
        DEF rightMotor RotationalMotor {
          name "rightMotor"
          maxVelocity 100
          maxTorque 100
        }
      ]
      endPoint Solid {
        translation -0.1815837872808982 -9.778643106411774e-05 -0.02985035860474213
        rotation -0.7083798431030043 -0.07767395655537038 -0.7015445490903606 3.286771546978697
        children [
          DEF rightWheel Shape {
            appearance PBRAppearance {
              baseColorMap ImageTexture {
                url [
                  "../assets/wheel.jpg"
                ]
                filtering 5
              }
              textureTransform TextureTransform {
              }
            }
            geometry Cylinder {
              height 0.01
              radius 0.03
            }
            castShadows FALSE
          }
        ]
        name "rightWheel"
        boundingObject USE rightWheel
        physics Physics {
        }
        linearVelocity 1.2080184550777016e-09 -1.9051761531369812e-10 7.438571136111684e-14
        angularVelocity 3.6776686724058683e-09 4.8384522436194233e-08 -3.3188056416215044e-09
      }
    }
    DEF body Shape {
      appearance PBRAppearance {
        metalness 0.5
      }
      geometry Cylinder {
        height 0.1
        radius 0.177
      }
      castShadows FALSE
    }
  ]
  boundingObject USE body
  physics Physics {
    centerOfMass [
      0 0 0
    ]
  }
  controller "bbAlr8"
  cpuConsumption 20
  linearVelocity 6.076800550788202e-10 -1.0385374206280732e-10 -2.2112902280973597e-12
  angularVelocity -1.1990671969946734e-11 1.46052922210478e-11 -3.298565487047278e-09
}
