#VRML_SIM R2023b utf8

EXTERNPROTO "https://raw.githubusercontent.com/cyberbotics/webots/R2023b/projects/objects/backgrounds/protos/TexturedBackground.proto"
EXTERNPROTO "https://raw.githubusercontent.com/cyberbotics/webots/R2023b/projects/objects/backgrounds/protos/TexturedBackgroundLight.proto"
EXTERNPROTO "../protos/RectangleArena.proto"
EXTERNPROTO "https://raw.githubusercontent.com/cyberbotics/webots/R2023b/projects/objects/apartment_structure/protos/Wall.proto"
EXTERNPROTO "https://raw.githubusercontent.com/cyberbotics/webots/R2023b/projects/appearances/protos/Roughcast.proto"

WorldInfo {
}
Viewpoint {
  orientation -0.03514405108658932 -0.004871083070196061 -0.9993703859045188 2.8993254688426413
  position 0.3265292778558887 -0.07102285649292193 0.012875249097819032
}
TexturedBackground {
}
TexturedBackgroundLight {
}
RectangleArena {
  floorSize 2.5 2.5
}
Wall {
  translation -1 0 0
  name "wall(14)"
  size 0.01 1 0.1
}
Wall {
  translation -0.25 1 0
  rotation 0 0 1 1.5707996938995747
  name "wall(21)"
  size 0.01 1 0.1
}
Wall {
  translation 0 0.5 0
  rotation 0 0 1 1.5707996938995747
  name "wall(25)"
  size 0.01 1 0.1
}
Wall {
  translation 0.5 -0.75 0
  rotation 0 0 1 1.5708
  name "wall(12)"
  size 0.01 0.5 0.1
}
Wall {
  translation 1 -0.25 0
  rotation 0 0 1 1.5708
  name "wall(33)"
  size 0.01 0.5 0.1
}
Wall {
  translation 0.95 -0.24 0
  rotation 0 0 1 1.5708
  name "wall(46)"
  size 0.01 0.1 0.1
  appearance Roughcast {
    colorOverride 0.647 0.412 0.118
    textureTransform TextureTransform {
      scale 2.4 1
    }
  }
}
Wall {
  translation 0.25 -0.25 0
  rotation 0 0 1 1.5708
  name "wall(36)"
  size 0.01 0.5 0.1
}
Wall {
  rotation 0 0 1 1.5708
  name "wall(41)"
  size 0.01 0.5 0.1
}
Wall {
  translation 0.75 -0.5 0
  rotation 0 0 1 1.5708
  name "wall(37)"
  size 0.01 0.5 0.1
}
Wall {
  translation -0.25 -0.5 0
  rotation 0 0 1 1.5708
  name "wall(50)"
  size 0.01 0.5 0.1
}
Wall {
  translation 0.55 -0.49 0
  rotation 0 0 1 1.5708
  name "wall(47)"
  size 0.01 0.1 0.1
  appearance Roughcast {
    colorOverride 1 0 1
    textureTransform TextureTransform {
      scale 2.4 1
    }
  }
}
Wall {
  translation 0.75 -0.875 0
  name "wall(4)"
  size 0.01 0.25 0.1
}
Wall {
  translation 1 -0.875 0
  name "wall(5)"
  size 0.01 0.25 0.1
}
Wall {
  translation 0 -1 0
  name "wall(6)"
  size 0.01 0.5 0.1
}
Wall {
  translation 1 0 0
  name "wall(34)"
  size 0.01 0.5 0.1
}
Wall {
  translation 0.5 -0.25 0
  name "wall(35)"
  size 0.01 0.5 0.1
}
Wall {
  translation -0.25 -0.25 0
  name "wall(40)"
  size 0.01 0.5 0.1
}
Wall {
  translation -0.75 -0.5 0
  name "wall(13)"
  size 0.01 1 0.1
}
Wall {
  translation -0.5 0.25 0
  name "wall(10)"
  size 0.01 1 0.1
}
Wall {
  translation 0.75 0.5 0
  name "wall(24)"
  size 0.01 1 0.1
}
Wall {
  translation 0.25 -1 0
  name "wall(7)"
  size 0.01 0.5 0.1
}
Wall {
  translation 0.25 -0.5 0
  name "wall(8)"
  size 0.01 0.5 0.1
}
Wall {
  translation -1.125 -1 0
  rotation 0 0 1 1.5708
  name "wall(3)"
  size 0.01 0.25 0.1
}
Wall {
  translation 0.125 -0.5 0
  rotation 0 0 1 1.5708
  name "wall(51)"
  size 0.01 0.25 0.1
}
Wall {
  translation -1.125 -0.5 0
  rotation 0 0 1 1.5708
  name "wall(15)"
  size 0.01 0.25 0.1
}
Wall {
  translation -1.125 -0.49 0
  rotation 0 0 1 1.5708
  name "wall(44)"
  size 0.01 0.1 0.1
  appearance Roughcast {
    colorOverride 0 1 0
    textureTransform TextureTransform {
      scale 2.4 1
    }
  }
}
Wall {
  translation -0.875 0.25 0
  rotation 0 0 1 1.5708
  name "wall(16)"
  size 0.01 0.25 0.1
}
Wall {
  translation -0.625 -0.25 0
  rotation 0 0 1 1.5708
  name "wall(52)"
  size 0.01 0.25 0.1
}
Wall {
  translation -0.875 0.75 0
  rotation 0 0 1 1.5708
  name "wall(17)"
  size 0.01 0.25 0.1
}
Wall {
  translation 0.875 1 0
  rotation 0 0 1 1.5708
  name "wall(23)"
  size 0.01 0.25 0.1
}
Wall {
  translation 1.125 0.75 0
  rotation 0 0 1 1.5708
  name "wall(30)"
  size 0.01 0.25 0.1
}
Wall {
  translation 1.125 0.5 0
  rotation 0 0 1 1.5708
  name "wall(31)"
  size 0.01 0.25 0.1
}
Wall {
  translation 1.125 -0.75 0
  rotation 0 0 1 1.5708
  name "wall(32)"
  size 0.01 0.25 0.1
}
Wall {
  translation 0.125 0.75 0
  rotation 0 0 1 1.5708
  name "wall(28)"
  size 0.01 0.25 0.1
}
Wall {
  translation 0.375 0.25 0
  rotation 0 0 1 1.5708
  name "wall(43)"
  size 0.01 0.25 0.1
}
Wall {
  translation 0.625 0.5 0
  rotation 0 0 1 1.5708
  name "wall(29)"
  size 0.01 0.25 0.1
}
Wall {
  translation 0.7 0.49 0
  rotation 0 0 1 1.5708
  name "wall(45)"
  size 0.01 0.1 0.1
  appearance Roughcast {
    colorOverride 1 0 0
    textureTransform TextureTransform {
      scale 2.4 1
    }
  }
}
Wall {
  translation -0.25 -0.75 0
  rotation 0 0 1 1.5708
  name "wall(2)"
  size 0.01 0.5 0.1
}
Wall {
  translation 0.05 -1.245 0
  rotation 0 0 1 1.5708
  name "wall(48)"
  size 0.01 0.1 0.1
  appearance Roughcast {
    colorOverride 1 1 0
    textureTransform TextureTransform {
      scale 2.4 1
    }
  }
}
Wall {
  translation -0.75 -0.75 0
  rotation 0 0 1 1.5708
  name "wall(11)"
  size 0.01 0.5 0.1
}
Wall {
  translation -0.5 -1.125 0
  size 0.01 0.25 0.1
}
Wall {
  translation -1 1.125 0
  name "wall(18)"
  size 0.01 0.25 0.1
}
Wall {
  translation -0.25 0.875 0
  name "wall(26)"
  size 0.01 0.25 0.1
}
Wall {
  translation 0 0.375 0
  name "wall(38)"
  size 0.01 0.25 0.1
}
Wall {
  translation 0.25 0.125 0
  name "wall(42)"
  size 0.01 0.25 0.1
}
Wall {
  translation -0.25 0.125 0
  name "wall(39)"
  size 0.01 0.25 0.1
}
Wall {
  translation 0 0.625 0
  name "wall(27)"
  size 0.01 0.25 0.1
}
Wall {
  translation 0.5 1 0
  name "wall(22)"
  size 0.01 0.5 0.1
}
Wall {
  translation -0.75 0.75 0
  name "wall(49)"
  size 0.01 0.5 0.1
}
Wall {
  translation -1 0.625 0
  name "wall(19)"
  size 0.01 0.25 0.1
}
Wall {
  translation -0.25 -0.875 0
  name "wall(9)"
  size 0.01 0.25 0.1
}
Wall {
  translation 0.5 -1.125 0
  name "wall(1)"
  size 0.01 0.25 0.1
}
Robot {
  translation -0.10837975740793916 -0.21816411284486378 0.01996125576392574
  rotation -0.007049744271518307 -0.0001686595512170855 0.9999751360207224 0.047409832438403555
  children [
    DEF downCam Camera {
      translation 8.98038e-08 0.032 -0.005
      rotation 3.69431e-07 -1 -1.0753e-06 -1.5708053071795867
      children [
        DEF dcam Shape {
          appearance PBRAppearance {
            baseColor 0 0 1
          }
          geometry Capsule {
            height 0.005
            radius 0.005
          }
        }
      ]
      boundingObject USE dcam
      physics Physics {
      }
    }
    DEF frontCam Camera {
      translation 0 0.028 0.01
      rotation 0.5773519358512958 0.5773519358512958 0.5773469358518515 2.0944
      children [
        DEF fcam Shape {
          appearance PBRAppearance {
            baseColor 1 0 0
          }
          geometry Capsule {
            height 0.005
            radius 0.005
          }
        }
      ]
      name "fcam"
      boundingObject USE fcam
      physics Physics {
      }
    }
    DEF rightIr DistanceSensor {
      translation 0.027 0.025 -0.008
      children [
        DEF rir Shape {
          appearance PBRAppearance {
          }
          geometry Box {
            size 0.005 0.005 0.01
          }
        }
      ]
      boundingObject USE rir
      physics Physics {
      }
    }
    DEF leftIr DistanceSensor {
      translation -0.027 0.025 -0.008
      rotation 0 0 1 3.14159
      children [
        DEF lir Shape {
          appearance PBRAppearance {
          }
          geometry Box {
            size 0.005 0.005 0.01
          }
        }
      ]
      name "distance sensor(1)"
      boundingObject USE lir
      physics Physics {
      }
    }
    DEF centerLeftIr DistanceSensor {
      translation -0.019 0.031 0.009
      rotation 0 0 -1 -1.5707953071795862
      children [
        DEF clir Shape {
          appearance PBRAppearance {
          }
          geometry Box {
            size 0.005 0.005 0.01
          }
        }
      ]
      name "distance sensor(2)"
      boundingObject USE clir
      physics Physics {
      }
    }
    DEF centerRightIr DistanceSensor {
      translation 0.019 0.031 0.009
      rotation 0 0 -1 -1.5707953071795862
      children [
        DEF clir Shape {
          appearance PBRAppearance {
          }
          geometry Box {
            size 0.005 0.005 0.01
          }
        }
      ]
      name "distance sensor(3)"
      boundingObject USE clir
      physics Physics {
      }
    }
    DEF right45Ir DistanceSensor {
      translation 0.019 0.031 -0.008
      rotation 0 0 1 0.7854
      children [
        DEF r45ir Shape {
          appearance PBRAppearance {
          }
          geometry Box {
            size 0.005 0.005 0.01
          }
        }
      ]
      name "distance sensor(4)"
      boundingObject USE r45ir
      physics Physics {
      }
    }
    DEF left45Ir DistanceSensor {
      translation -0.019 0.031 -0.008
      rotation 0 0 1 2.3562
      children [
        DEF l45ir Shape {
          appearance PBRAppearance {
          }
          geometry Box {
            size 0.005 0.005 0.01
          }
        }
      ]
      name "distance sensor(5)"
      boundingObject USE l45ir
      physics Physics {
      }
    }
    DEF castor Solid {
      translation 0 0.025 -0.015
      children [
        DEF castor Shape {
          appearance PBRAppearance {
          }
          geometry Sphere {
            radius 0.005
          }
        }
      ]
      boundingObject USE castor
      physics Physics {
      }
    }
    HingeJoint {
      jointParameters HingeJointParameters {
        position -4.050900210797558e-08
      }
      device [
        PositionSensor {
        }
        RotationalMotor {
        }
      ]
      endPoint Solid {
        translation 0.030000000000000002 -0.010000100000000603 -1.537279174745128e-08
        rotation -1.5935839002282485e-08 0.9999999999999997 -1.7078369714058076e-08 1.5708000076550765
        children [
          DEF leftWheel Shape {
            appearance PBRAppearance {
              baseColorMap ImageTexture {
                url [
                  "../assets/wheel.jpg"
                ]
              }
            }
            geometry Cylinder {
              height 0.01
              radius 0.02
            }
          }
        ]
        name "leftWheel"
        boundingObject USE leftWheel
        physics Physics {
        }
        linearVelocity -4.8224047245276125e-11 1.0174843143663583e-09 8.445574221426687e-12
        angularVelocity -6.345485902869464e-08 -3.0106331778573806e-09 1.4657437771791595e-11
      }
    }
    HingeJoint {
      jointParameters HingeJointParameters {
        position -7.257458628504916e-08
      }
      device [
        PositionSensor {
        }
        RotationalMotor {
        }
      ]
      endPoint Solid {
        translation -0.029999999999999853 -0.010000100000000576 -1.7006092429569338e-08
        rotation -4.3842464802021986e-08 0.9999999999999981 -4.330354085503046e-08 1.5707999925118334
        children [
          DEF rightWheel Shape {
            appearance PBRAppearance {
              baseColorMap ImageTexture {
                url [
                  "../assets/wheel.jpg"
                ]
                filtering 5
              }
              textureTransform TextureTransform {
              }
            }
            geometry Cylinder {
              height 0.01
              radius 0.02
            }
          }
        ]
        name "rightWheel"
        boundingObject USE rightWheel
        physics Physics {
        }
        linearVelocity -4.832115373096486e-11 1.017469642427839e-09 8.445008789857113e-12
        angularVelocity -6.345426089593355e-08 -3.010494228522914e-09 -1.452020037347388e-11
      }
    }
    DEF body Shape {
      appearance PBRAppearance {
        baseColor 0.1 0.1 0.1
        metalness 0.5
      }
      geometry Box {
        size 0.05 0.06 0.03
      }
    }
  ]
  boundingObject USE body
  physics Physics {
  }
  linearVelocity -2.5329328508929865e-11 5.3390845158814e-10 -5.983785366393672e-10
  angularVelocity 2.376092951499727e-08 1.127432932736264e-09 7.480592787916816e-14
}
